<?xml version="1.0"?>
<robot name="RAS_Rover">

  <!--Materials for links-->
  <material name="yellow">
    <color rgba="1 1 0 1" />
  </material>

  <material name="blue">
    <color rgba="0 0 1 1" />
  </material>

  <material name="grey">
    <color rgba="0.7 0.7 0.7 1" />
  </material>

  <material name="white">
    <color rgba="1 1 1 1" />
  </material>

  <!--Base box-->
  <link name="base_link">
    <inertial>
      <mass value="2.0"/>
      <origin xyz="0 0 0" rpy="0 0 0"/>
      <inertia ixx="0.0167" ixy="0" ixz="0"
               iyy="0.0217" iyz="0"
               izz="0.05"/>
    </inertial>
    <visual>
      <geometry>
        <box size="0.6 0.4 0.1"/>
      </geometry>
      <origin xyz="0 0 0.1" rpy="0 0 0"/>
      <material name="yellow"/>
    </visual>
    
    <!--Collision tag to prevent the rover from falling through the ground-->
    <collision>
      <geometry>
        <box size="0.3 0.3 0.3"/>
      </geometry>
      <origin xyz="0 0 0.1" rpy="0 0 0"/>
    </collision>

    <!--Gazebo tags for color-->
    <gazebo reference = "chassis">
      <material>Gazebo/White</material>
    </gazebo>

  </link>

  <!--Lidar-->
  <link name="lidar">
    <inertial>
      <mass value="0.3"/>
      <origin xyz="0 0 0" rpy="0 0 0"/>
      <inertia ixx="0.0003" ixy="0" ixz="0"
               iyy="0.0003" iyz="0"
               izz="0.0001"/>
    </inertial>
    <visual>
      <geometry>
        <cylinder radius="0.1" length="0.0225"/>
      </geometry>
      <origin xyz="0 0 0" rpy="0 0 0"/>
      <material name="white"/>
    </visual>
    
    <!--Collision tag to prevent the rover from falling through the ground-->
    <collision>
      <geometry>
        <cylinder radius="0.1" length="0.0225"/>
      </geometry>
      <origin xyz="0 0 0" rpy="0 0 0"/>
    </collision>

    <!--Gazebo tags for color-->
    <gazebo reference = "lidar">
      <material>Gazebo/Grey</material>
    </gazebo>
  </link>

  <joint name="base_lidar_joint" type="fixed">
    <parent link="base_link"/>
    <child link="lidar"/>
    <origin xyz="0 0 0.16" rpy="0 0 0"/>
  </joint>

  <!--Wheels-->
  <!-- Mass for each wheel: 0.5 kg -->
  <!-- Inertia computed for cylinder (radius=0.1m, length=0.05m) -->

  <link name="left_wheel_1">
    <inertial>
      <mass value="0.5"/>
      <origin xyz="0 0 0" rpy="0 0 0"/>
        <inertia ixx="0.0014" ixy="0" ixz="0"
               iyy="0.0014" iyz="0"
               izz="0.0025"/>
    </inertial>
    <visual>
      <geometry>
        <cylinder radius="0.1" length="0.05"/>
      </geometry>
      <origin xyz="0 0 0" rpy="1.57 0 0"/>
      <material name="blue"/>
    </visual>
    
    <!--Collision tag to prevent the rover from falling through the ground-->
    <collision>
      <geometry>
        <cylinder radius="0.1" length="0.05"/>
      </geometry>
      <origin xyz="0 0 0" rpy="1.57 0 0"/>
    </collision>

    <!--Gazebo tags for color-->
    <gazebo reference = "left_wheel_1">
      <material>Gazebo/Blue</material>
    </gazebo>

  </link>

  <joint name="base_left_wheel_joint_1" type="continuous">
    <parent link="base_link"/>
    <child link="left_wheel_1"/>
    <origin xyz="0 0.225 0" rpy="0 0 0"/>
    <axis xyz="0 1 0"/>
  </joint>

  <link name="left_wheel_2">
    <inertial>
      <mass value="0.5"/>
      <origin xyz="0 0 0" rpy="0 0 0"/>
        <inertia ixx="0.0014" ixy="0" ixz="0"
               iyy="0.0014" iyz="0"
               izz="0.0025"/>
    </inertial>
    <visual>
      <geometry>
        <cylinder radius="0.1" length="0.05"/>
      </geometry>
      <origin xyz="0 0 0" rpy="1.57 0 0"/>
      <material name="blue"/>
    </visual>
    
    <!--Collision tag to prevent the rover from falling through the ground-->
    <collision>
      <geometry>
        <cylinder radius="0.1" length="0.05"/>
      </geometry>
      <origin xyz="0 0 0" rpy="1.57 0 0"/>
    </collision>

    <!--Gazebo tags for color-->
    <gazebo reference = "left_wheel_2">
      <material>Gazebo/Blue</material>
    </gazebo>
  </link>

  <joint name="base_left_wheel_joint_2" type="continuous">
    <parent link="base_link"/>
    <child link="left_wheel_2"/>
    <origin xyz="-0.3 0.225 0" rpy="0 0 0"/>
    <axis xyz="0 1 0"/>
  </joint>

  <link name="left_wheel_3">
    <inertial>
      <mass value="0.5"/>
      <origin xyz="0 0 0" rpy="0 0 0"/>
        <inertia ixx="0.0014" ixy="0" ixz="0"
               iyy="0.0014" iyz="0"
               izz="0.0025"/>
    </inertial>
    <visual>
      <geometry>
        <cylinder radius="0.1" length="0.05"/>
      </geometry>
      <origin xyz="0 0 0" rpy="1.57 0 0"/>
      <material name="blue"/>
    </visual>
    
    <!--Collision tag to prevent the rover from falling through the ground-->
    <collision>
      <geometry>
        <cylinder radius="0.1" length="0.05"/>
      </geometry>
      <origin xyz="0 0 0" rpy="1.57 0 0"/>
    </collision>

    <!--Gazebo tags for color-->
    <gazebo reference = "left_wheel_3">
      <material>Gazebo/Blue</material>
    </gazebo>
  </link>

  <joint name="base_left_wheel_joint_3" type="continuous">
    <parent link="base_link"/>
    <child link="left_wheel_3"/>
    <origin xyz="0.3 0.225 0" rpy="0 0 0"/>
    <axis xyz="0 1 0"/>
  </joint>

  <link name="right_wheel_1">
    <inertial>
      <mass value="0.5"/>
      <origin xyz="0 0 0" rpy="0 0 0"/>
        <inertia ixx="0.0014" ixy="0" ixz="0"
               iyy="0.0014" iyz="0"
               izz="0.0025"/>
    </inertial>
    <visual>
      <geometry>
        <cylinder radius="0.1" length="0.05"/>
      </geometry>
      <origin xyz="0 0 0" rpy="1.57 0 0"/>
      <material name="blue"/>
    </visual>
    
    <!--Collision tag to prevent the rover from falling through the ground-->
    <collision>
      <geometry>
        <cylinder radius="0.1" length="0.05"/>
      </geometry>
      <origin xyz="0 0 0" rpy="1.57 0 0"/>
    </collision>

    <!--Gazebo tags for color-->
    <gazebo reference = "right_wheel_1">
      <material>Gazebo/Blue</material>
    </gazebo>
  </link>

  <joint name="base_right_wheel_joint_1" type="continuous">
    <parent link="base_link"/>
    <child link="right_wheel_1"/>
    <origin xyz="0 -0.225 0" rpy="0 0 0"/>
    <axis xyz="0 1 0"/>
  </joint>

  <link name="right_wheel_2">
    <inertial>
      <mass value="0.5"/>
      <origin xyz="0 0 0" rpy="0 0 0"/>
        <inertia ixx="0.0014" ixy="0" ixz="0"
               iyy="0.0014" iyz="0"
               izz="0.0025"/>
    </inertial>
    <visual>
      <geometry>
        <cylinder radius="0.1" length="0.05"/>
      </geometry>
      <origin xyz="0 0 0" rpy="1.57 0 0"/>
      <material name="blue"/>
    </visual>
    
    <!--Collision tag to prevent the rover from falling through the ground-->
    <collision>
      <geometry>
        <cylinder radius="0.1" length="0.05"/>
      </geometry>
      <origin xyz="0 0 0" rpy="1.57 0 0"/>
    </collision>

    <!--Gazebo tags for color-->
    <gazebo reference = "right_wheel_2">
      <material>Gazebo/Blue</material>
    </gazebo>
  </link>

  <joint name="base_right_wheel_joint_2" type="continuous">
    <parent link="base_link"/>
    <child link="right_wheel_2"/>
    <origin xyz="-0.3 -0.225 0" rpy="0 0 0"/>
    <axis xyz="0 1 0"/>
  </joint>
  
  <link name="right_wheel_3">
    <inertial>
      <mass value="0.5"/>
      <origin xyz="0 0 0" rpy="0 0 0"/>
        <inertia ixx="0.0014" ixy="0" ixz="0"
               iyy="0.0014" iyz="0"
               izz="0.0025"/>
    </inertial>
    <visual>
      <geometry>
        <cylinder radius="0.1" length="0.05"/>
      </geometry>
      <origin xyz="0 0 0" rpy="1.57 0 0"/>
      <material name="blue"/>
    </visual>
    
    <!--Collision tag to prevent the rover from falling through the ground-->
    <collision>
      <geometry>
        <cylinder radius="0.1" length="0.05"/>
      </geometry>
      <origin xyz="0 0 0" rpy="1.57 0 0"/>
    </collision>

    <!--Gazebo tags for color-->
    <gazebo reference = "right_wheel_3">
      <material>Gazebo/Blue</material>
    </gazebo>
  </link>

  <joint name="base_right_wheel_joint_3" type="continuous">
    <parent link="base_link"/>
    <child link="right_wheel_3"/>
    <origin xyz="0.3 -0.225 0" rpy="0 0 0"/>
    <axis xyz="0 1 0"/>
  </joint>

  <!--Base foot-->
  <link name="base_footprint"/>

  <joint name="base_footprint_joint" type="fixed">
    <parent link="base_footprint"/>
    <child link="base_link"/>
    <origin xyz="0 0 0.1" rpy="0 0 0"/>
  </joint>

</robot>

